<?xml version="1.0" ?>
<robot name="mitarm" xmlns:xacro="http://www.ros.org/wiki/xacro">

<xacro:include filename="$(find mitarm_description)/urdf/materials.xacro" />
<xacro:include filename="$(find mitarm_description)/urdf/mitarm.trans" />
<xacro:include filename="$(find mitarm_description)/urdf/mitarm.gazebo" />
<link name="base_link">
  <inertial>
    <origin xyz="0.0007225318145799458 0.0002347648176890952 0.007530286128890356" rpy="0 0 0"/>
    <mass value="0.2613815524136642"/>
    <inertia ixx="0.000388" iyy="0.000377" izz="0.000755" ixy="4e-06" iyz="-0.0" ixz="-1e-06"/>
  </inertial>
  <visual>
    <origin xyz="0 0 0" rpy="0 0 0"/>
    <geometry>
      <mesh filename="package://mitarm_description/meshes/base_link.stl" scale="0.001 0.001 0.001"/>
    </geometry>
    <material name="silver"/>
  </visual>
  <collision>
    <origin xyz="0 0 0" rpy="0 0 0"/>
    <geometry>
      <mesh filename="package://mitarm_description/meshes/base_link.stl" scale="0.001 0.001 0.001"/>
    </geometry>
  </collision>
</link>

<link name="servo_holder_1">
  <inertial>
    <origin xyz="-0.0003870250413150145 3.9263820049963354e-11 0.03337273576954071" rpy="0 0 0"/>
    <mass value="0.32713628516416926"/>
    <inertia ixx="0.000735" iyy="0.000717" izz="0.001307" ixy="0.0" iyz="0.0" ixz="1e-06"/>
  </inertial>
  <visual>
    <origin xyz="-0.0 -0.0 -0.015" rpy="0 0 0"/>
    <geometry>
      <mesh filename="package://mitarm_description/meshes/servo_holder_1.stl" scale="0.001 0.001 0.001"/>
    </geometry>
    <material name="silver"/>
  </visual>
  <collision>
    <origin xyz="-0.0 -0.0 -0.015" rpy="0 0 0"/>
    <geometry>
      <mesh filename="package://mitarm_description/meshes/servo_holder_1.stl" scale="0.001 0.001 0.001"/>
    </geometry>
  </collision>
</link>

<link name="orange_ring_1">
  <inertial>
    <origin xyz="-7.958230150670094e-14 6.100553000211611e-14 0.002250000000000002" rpy="0 0 0"/>
    <mass value="0.022558641945082187"/>
    <inertia ixx="5.3e-05" iyy="5.3e-05" izz="0.000107" ixy="-0.0" iyz="0.0" ixz="0.0"/>
  </inertial>
  <visual>
    <origin xyz="-0.0 -0.0 -0.065" rpy="0 0 0"/>
    <geometry>
      <mesh filename="package://mitarm_description/meshes/orange_ring_1.stl" scale="0.001 0.001 0.001"/>
    </geometry>
    <material name="silver"/>
  </visual>
  <collision>
    <origin xyz="-0.0 -0.0 -0.065" rpy="0 0 0"/>
    <geometry>
      <mesh filename="package://mitarm_description/meshes/orange_ring_1.stl" scale="0.001 0.001 0.001"/>
    </geometry>
  </collision>
</link>

<link name="shoulder_1">
  <inertial>
    <origin xyz="0.0001118512110484805 -7.858949452733166e-17 0.02595950050615324" rpy="0 0 0"/>
    <mass value="0.368012692921962"/>
    <inertia ixx="0.000846" iyy="0.000764" izz="0.001096" ixy="-0.0" iyz="-0.0" ixz="1e-06"/>
  </inertial>
  <visual>
    <origin xyz="-0.0 -0.0 -0.0695" rpy="0 0 0"/>
    <geometry>
      <mesh filename="package://mitarm_description/meshes/shoulder_1.stl" scale="0.001 0.001 0.001"/>
    </geometry>
    <material name="silver"/>
  </visual>
  <collision>
    <origin xyz="-0.0 -0.0 -0.0695" rpy="0 0 0"/>
    <geometry>
      <mesh filename="package://mitarm_description/meshes/shoulder_1.stl" scale="0.001 0.001 0.001"/>
    </geometry>
  </collision>
</link>

<link name="bicep_1">
  <inertial>
    <origin xyz="0.09323815503254468 0.02940616409136899 1.820799583329702e-08" rpy="0 0 0"/>
    <mass value="0.488316018042516"/>
    <inertia ixx="0.00054" iyy="0.001965" izz="0.002185" ixy="-3.8e-05" iyz="0.0" ixz="0.0"/>
  </inertial>
  <visual>
    <origin xyz="-0.0 0.0284 -0.135" rpy="0 0 0"/>
    <geometry>
      <mesh filename="package://mitarm_description/meshes/bicep_1.stl" scale="0.001 0.001 0.001"/>
    </geometry>
    <material name="silver"/>
  </visual>
  <collision>
    <origin xyz="-0.0 0.0284 -0.135" rpy="0 0 0"/>
    <geometry>
      <mesh filename="package://mitarm_description/meshes/bicep_1.stl" scale="0.001 0.001 0.001"/>
    </geometry>
  </collision>
</link>

<link name="elbow_1">
  <inertial>
    <origin xyz="0.06935481660081327 0.01843471639721764 0.001557576303791386" rpy="0 0 0"/>
    <mass value="0.41095625041627304"/>
    <inertia ixx="0.000331" iyy="0.000896" izz="0.000973" ixy="-3e-06" iyz="0.0" ixz="-1.3e-05"/>
  </inertial>
  <visual>
    <origin xyz="-0.185 0.0184 -0.135" rpy="0 0 0"/>
    <geometry>
      <mesh filename="package://mitarm_description/meshes/elbow_1.stl" scale="0.001 0.001 0.001"/>
    </geometry>
    <material name="silver"/>
  </visual>
  <collision>
    <origin xyz="-0.185 0.0184 -0.135" rpy="0 0 0"/>
    <geometry>
      <mesh filename="package://mitarm_description/meshes/elbow_1.stl" scale="0.001 0.001 0.001"/>
    </geometry>
  </collision>
</link>

<link name="forearm_1">
  <inertial>
    <origin xyz="0.04843860215732515 -0.0001360148751786914 7.370396379019484e-05" rpy="0 0 0"/>
    <mass value="0.11130884365182603"/>
    <inertia ixx="2e-05" iyy="0.000127" izz="0.000125" ixy="0.0" iyz="-0.0" ixz="0.0"/>
  </inertial>
  <visual>
    <origin xyz="-0.2975 0.0 -0.135956" rpy="0 0 0"/>
    <geometry>
      <mesh filename="package://mitarm_description/meshes/forearm_1.stl" scale="0.001 0.001 0.001"/>
    </geometry>
    <material name="silver"/>
  </visual>
  <collision>
    <origin xyz="-0.2975 0.0 -0.135956" rpy="0 0 0"/>
    <geometry>
      <mesh filename="package://mitarm_description/meshes/forearm_1.stl" scale="0.001 0.001 0.001"/>
    </geometry>
  </collision>
</link>

<link name="wrist_1">
  <inertial>
    <origin xyz="0.040568256623747245 0.016625106888881306 0.0023665708399699947" rpy="0 0 0"/>
    <mass value="0.2607706314227234"/>
    <inertia ixx="0.000249" iyy="0.000315" izz="0.000404" ixy="1.3e-05" iyz="1e-06" ixz="-1.6e-05"/>
  </inertial>
  <visual>
    <origin xyz="-0.3775 0.01474 -0.135956" rpy="0 0 0"/>
    <geometry>
      <mesh filename="package://mitarm_description/meshes/wrist_1.stl" scale="0.001 0.001 0.001"/>
    </geometry>
    <material name="silver"/>
  </visual>
  <collision>
    <origin xyz="-0.3775 0.01474 -0.135956" rpy="0 0 0"/>
    <geometry>
      <mesh filename="package://mitarm_description/meshes/wrist_1.stl" scale="0.001 0.001 0.001"/>
    </geometry>
  </collision>
</link>

<link name="palm_1">
  <inertial>
    <origin xyz="0.029689630044196946 -8.294476216974544e-15 0.004234416458535867" rpy="0 0 0"/>
    <mass value="0.04910424116673452"/>
    <inertia ixx="2e-05" iyy="5.4e-05" izz="4.5e-05" ixy="-0.0" iyz="0.0" ixz="-2e-06"/>
  </inertial>
  <visual>
    <origin xyz="-0.4675 0.0 -0.136441" rpy="0 0 0"/>
    <geometry>
      <mesh filename="package://mitarm_description/meshes/palm_1.stl" scale="0.001 0.001 0.001"/>
    </geometry>
    <material name="silver"/>
  </visual>
  <collision>
    <origin xyz="-0.4675 0.0 -0.136441" rpy="0 0 0"/>
    <geometry>
      <mesh filename="package://mitarm_description/meshes/palm_1.stl" scale="0.001 0.001 0.001"/>
    </geometry>
  </collision>
</link>

<link name="finger_left_1">
  <inertial>
    <origin xyz="0.016013217466136598 0.013826604272114636 0.009745141385066741" rpy="0 0 0"/>
    <mass value="0.03198293553605045"/>
    <inertia ixx="6e-06" iyy="2.2e-05" izz="2.6e-05" ixy="-4e-06" iyz="-0.0" ixz="-2e-06"/>
  </inertial>
  <visual>
    <origin xyz="-0.53625 0.0 -0.124191" rpy="0 0 0"/>
    <geometry>
      <mesh filename="package://mitarm_description/meshes/finger_left_1.stl" scale="0.001 0.001 0.001"/>
    </geometry>
    <material name="silver"/>
  </visual>
  <collision>
    <origin xyz="-0.53625 0.0 -0.124191" rpy="0 0 0"/>
    <geometry>
      <mesh filename="package://mitarm_description/meshes/finger_left_1.stl" scale="0.001 0.001 0.001"/>
    </geometry>
  </collision>
</link>

<link name="finger_right_1">
  <inertial>
    <origin xyz="0.009988641771545681 -0.017284532680518373 -0.009147534981625433" rpy="0 0 0"/>
    <mass value="0.03292577094713501"/>
    <inertia ixx="1e-05" iyy="4e-05" izz="4.9e-05" ixy="4e-06" iyz="-1e-06" ixz="3e-06"/>
  </inertial>
  <visual>
    <origin xyz="-0.53625 0.0 -0.148691" rpy="0 0 0"/>
    <geometry>
      <mesh filename="package://mitarm_description/meshes/finger_right_1.stl" scale="0.001 0.001 0.001"/>
    </geometry>
    <material name="silver"/>
  </visual>
  <collision>
    <origin xyz="-0.53625 0.0 -0.148691" rpy="0 0 0"/>
    <geometry>
      <mesh filename="package://mitarm_description/meshes/finger_right_1.stl" scale="0.001 0.001 0.001"/>
    </geometry>
  </collision>
</link>

<joint name="servo_holder_joint" type="fixed">
  <origin xyz="0.0 0.0 0.015" rpy="0 0 0"/>
  <parent link="base_link"/>
  <child link="servo_holder_1"/>
</joint>

<joint name="bearing_joint" type="fixed">
  <origin xyz="0.0 0.0 0.05" rpy="0 0 0"/>
  <parent link="servo_holder_1"/>
  <child link="orange_ring_1"/>
</joint>

<joint name="base_revolute" type="revolute">
  <origin xyz="0.0 0.0 0.0045" rpy="0 0 0"/>
  <parent link="orange_ring_1"/>
  <child link="shoulder_1"/>
  <axis xyz="0.0 -0.0 1.0"/>
  <limit upper="1.570796" lower="-1.570796" effort="100" velocity="100"/>
</joint>

<joint name="shoulder_joint" type="revolute">
  <origin xyz="0.0 -0.0284 0.0655" rpy="0 0 0"/>
  <parent link="shoulder_1"/>
  <child link="bicep_1"/>
  <axis xyz="-0.0 1.0 -0.0"/>
  <limit upper="0.0" lower="-3.141593" effort="100" velocity="100"/>
</joint>

<joint name="elbow_joint" type="revolute">
  <origin xyz="0.185 0.01 0.0" rpy="0 0 0"/>
  <parent link="bicep_1"/>
  <child link="elbow_1"/>
  <axis xyz="-0.0 1.0 -0.0"/>
  <limit upper="1.832596" lower="0.0" effort="100" velocity="100"/>
</joint>

<joint name="elbow_twist" type="revolute">
  <origin xyz="0.1125 0.0184 0.000956" rpy="0 0 0"/>
  <parent link="elbow_1"/>
  <child link="forearm_1"/>
  <axis xyz="1.0 0.0 -0.0"/>
  <limit upper="1.570796" lower="-1.570796" effort="100" velocity="100"/>
</joint>

<joint name="wrist_joint" type="revolute">
  <origin xyz="0.08 -0.01474 0.0" rpy="0 0 0"/>
  <parent link="forearm_1"/>
  <child link="wrist_1"/>
  <axis xyz="0.0 -1.0 0.0"/>
  <limit upper="1.570796" lower="-1.570796" effort="100" velocity="100"/>
</joint>

<joint name="wrist_twist" type="revolute">
  <origin xyz="0.09 0.01474 0.000485" rpy="0 0 0"/>
  <parent link="wrist_1"/>
  <child link="palm_1"/>
  <axis xyz="1.0 0.0 -0.0"/>
  <limit upper="1.570796" lower="-1.570796" effort="100" velocity="100"/>
</joint>

<joint name="finger_left_joint" type="revolute">
  <origin xyz="0.06875 0.0 -0.01225" rpy="0 0 0"/>
  <parent link="palm_1"/>
  <child link="finger_left_1"/>
  <axis xyz="-0.0 0.0 -1.0"/>
  <limit upper="0.0" lower="-1.308997" effort="100" velocity="100"/>
</joint>

<joint name="finger_right_joint" type="revolute">
  <origin xyz="0.06875 0.0 0.01225" rpy="0 0 0"/>
  <parent link="palm_1"/>
  <child link="finger_right_1"/>
  <axis xyz="-0.0 0.0 -1.0"/>
  <limit upper="1.308997" lower="0.0" effort="100" velocity="100"/>
</joint>

</robot>
